Workbook

Sheet README
A1: Supplementary Material S3. Empirical evaluation of five extraction tools on five marine and coastal research articles
A3: Contents
A4: S3.0 Pooled results – Table 6 of the main text, calculated by formula from S3.1.
A5: S3.1 Per-article counts – correct/assessed items for every measure, article and tool, with harmonisation notes.
A6: S3.2 Test articles – the five articles, their document type, numbers of tables and figures, and why each was included.
A7: S3.3 Tool versions – version, run mode, settings, hardware, licence and repository for each tool.
A8: S3.4 Assessment notes – original per-article scoring notes recorded during manual assessment.
A10: Conventions
A11: NS = not supported by tool design; n.s. = not scored; blank = not scored or not run.
A12: Denominators include every item in the source article, so items missing from an output count as failures.
A13: Blue numbers in S3.1 are manual assessment counts; black cells are formulas; yellow cells in S3.3 are still to be completed.
A15: Before submission: complete S3.3 and delete this line.

Sheet S3.0 Pooled results
A1: Table S3.0 (= Table 6 in the main text). Performance of five full-document and table-extraction tools on five marine and coastal research articles (pooled counts across articles; correct / assessed, %).
A3: Block | B3: Measure | C3: Operational definition | D3: Docling | E3: Nougat | F3: PP-StructureV2 | G3: olmOCR 2 | H3: Tabula
A4: A. Document reconstruction | B4: Text fidelity | C4: Correct normalised word tokens / reference tokens (abstract) | D4: =IF(COUNTIFS('S3.1 Per-article counts'!$A$2:$A$48,$B4,'S3.1 Per-article counts'!$C$2:$C$48,"NS")>0,"Not supported",IF(SUMIFS('S3.1 Per-article counts'!$D$2:$D$48,'S3.1 Per-article counts'!$A$2:$A$48,$B4)=0,"Not scored",SUMIFS('S3.1 Per-article counts'!$C$2:$C$48,'S3.1 Per-article counts'!$A$2:$A$48,$B4)&"/"&SUMIFS('S3.1 Per-article counts'!$D$2:$D$48,'S3.1 Per-article counts'!$A$2:$A$48,$B4)&" ("&TEXT(SUMIFS('S3.1 Per-article counts'!$C$2:$C$48,'S3.1 Per-article counts'!$A$2:$A$48,$B4)/SUMIFS('S3.1 Per-article counts'!$D$2:$D$48,'S3.1 Per-article counts'!$A$2:$A$48,$B4),"0.0%")&")"&IF(COUNTIFS('S3.1 Per-article counts'!$A$2:$A$48,$B4,'S3.1 Per-article counts'!$D$2:$D$48,">0")<5," [k="&COUNTIFS('S3.1 Per-article counts'!$A$2:$A$48,$B4,'S3.1 Per-article counts'!$D$2:$D$48,">0")&"/5]",""))) -> 1261/1265 (99.7%) | E4: =IF(COUNTIFS('S3.1 Per-article counts'!$A$2:$A$48,$B4,'S3.1 Per-article counts'!$E$2:$E$48,"NS")>0,"Not supported",IF(SUMIFS('S3.1 Per-article counts'!$F$2:$F$48,'S3.1 Per-article counts'!$A$2:$A$48,$B4)=0,"Not scored",SUMIFS('S3.1 Per-article counts'!$E$2:$E$48,'S3.1 Per-article counts'!$A$2:$A$48,$B4)&"/"&SUMIFS('S3.1 Per-article counts'!$F$2:$F$48,'S3.1 Per-article counts'!$A$2:$A$48,$B4)&" ("&TEXT(SUMIFS('S3.1 Per-article counts'!$E$2:$E$48,'S3.1 Per-article counts'!$A$2:$A$48,$B4)/SUMIFS('S3.1 Per-article counts'!$F$2:$F$48,'S3.1 Per-article counts'!$A$2:$A$48,$B4),"0.0%")&")"&IF(COUNTIFS('S3.1 Per-article counts'!$A$2:$A$48,$B4,'S3.1 Per-article counts'!$F$2:$F$48,">0")<5," [k="&COUNTIFS('S3.1 Per-article counts'!$A$2:$A$48,$B4,'S3.1 Per-article counts'!$F$2:$F$48,">0")&"/5]",""))) -> 683/1265 (54.0%) | F4: =IF(COUNTIFS('S3.1 Per-article counts'!$A$2:$A$48,$B4,'S3.1 Per-article counts'!$G$2:$G$48,"NS")>0,"Not supported",IF(SUMIFS('S3.1 Per-article counts'!$H$2:$H$48,'S3.1 Per-article counts'!$A$2:$A$48,$B4)=0,"Not scored",SUMIFS('S3.1 Per-article counts'!$G$2:$G$48,'S3.1 Per-article counts'!$A$2:$A$48,$B4)&"/"&SUMIFS('S3.1 Per-article counts'!$H$2:$H$48,'S3.1 Per-article counts'!$A$2:$A$48,$B4)&" ("&TEXT(SUMIFS('S3.1 Per-article counts'!$G$2:$G$48,'S3.1 Per-article counts'!$A$2:$A$48,$B4)/SUMIFS('S3.1 Per-article counts'!$H$2:$H$48,'S3.1 Per-article counts'!$A$2:$A$48,$B4),"0.0%")&")"&IF(COUNTIFS('S3.1 Per-article counts'!$A$2:$A$48,$B4,'S3.1 Per-article counts'!$H$2:$H$48,">0")<5," [k="&COUNTIFS('S3.1 Per-article counts'!$A$2:$A$48,$B4,'S3.1 Per-article counts'!$H$2:$H$48,">0")&"/5]",""))) -> 1221/1265 (96.5%) | G4: =IF(COUNTIFS('S3.1 Per-article counts'!$A$2:$A$48,$B4,'S3.1 Per-article counts'!$I$2:$I$48,"NS")>0,"Not supported",IF(SUMIFS('S3.1 Per-article counts'!$J$2:$J$48,'S3.1 Per-article counts'!$A$2:$A$48,$B4)=0,"Not scored",SUMIFS('S3.1 Per-article counts'!$I$2:$I$48,'S3.1 Per-article counts'!$A$2:$A$48,$B4)&"/"&SUMIFS('S3.1 Per-article counts'!$J$2:$J$48,'S3.1 Per-article counts'!$A$2:$A$48,$B4)&" ("&TEXT(SUMIFS('S3.1 Per-article counts'!$I$2:$I$48,'S3.1 Per-article counts'!$A$2:$A$48,$B4)/SUMIFS('S3.1 Per-article counts'!$J$2:$J$48,'S3.1 Per-article counts'!$A$2:$A$48,$B4),"0.0%")&")"&IF(COUNTIFS('S3.1 Per-article counts'!$A$2:$A$48,$B4,'S3.1 Per-article counts'!$J$2:$J$48,">0")<5," [k="&COUNTIFS('S3.1 Per-article counts'!$A$2:$A$48,$B4,'S3.1 Per-article counts'!$J$2:$J$48,">0")&"/5]",""))) -> 1068/1078 (99.1%) [k=4/5] | H4: =IF(COUNTIFS('S3.1 Per-article counts'!$A$2:$A$48,$B4,'S3.1 Per-article counts'!$K$2:$K$48,"NS")>0,"Not supported",IF(SUMIFS('S3.1 Per-article counts'!$L$2:$L$48,'S3.1 Per-article counts'!$A$2:$A$48,$B4)=0,"Not scored",SUMIFS('S3.1 Per-article counts'!$K$2:$K$48,'S3.1 Per-article counts'!$A$2:$A$48,$B4)&"/"&SUMIFS('S3.1 Per-article counts'!$L$2:$L$48,'S3.1 Per-article counts'!$A$2:$A$48,$B4)&" ("&TEXT(SUMIFS('S3.1 Per-article counts'!$K$2:$K$48,'S3.1 Per-article counts'!$A$2:$A$48,$B4)/SUMIFS('S3.1 Per-article counts'!$L$2:$L$48,'S3.1 Per-article counts'!$A$2:$A$48,$B4),"0.0%")&")"&IF(COUNTIFS('S3.1 Per-article counts'!$A$2:$A$48,$B4,'S3.1 Per-article counts'!$L$2:$L$48,">0")<5," [k="&COUNTIFS('S3.1 Per-article counts'!$A$2:$A$48,$B4,'S3.1 Per-article counts'!$L$2:$L$48,">0")&"/5]",""))) -> Not supported
A5: A. Document reconstruction | B5: Reading continuity | C5: Numbered objects inserted without interrupting a body sentence / all numbered objects | D5: =IF(COUNTIFS('S3.1 Per-article counts'!$A$2:$A$48,$B5,'S3.1 Per-article counts'!$C$2:$C$48,"NS")>0,"Not supported",IF(SUMIFS('S3.1 Per-article counts'!$D$2:$D$48,'S3.1 Per-article counts'!$A$2:$A$48,$B5)=0,"Not scored",SUMIFS('S3.1 Per-article counts'!$C$2:$C$48,'S3.1 Per-article counts'!$A$2:$A$48,$B5)&"/"&SUMIFS('S3.1 Per-article counts'!$D$2:$D$48,'S3.1 Per-article counts'!$A$2:$A$48,$B5)&" ("&TEXT(SUMIFS('S3.1 Per-article counts'!$C$2:$C$48,'S3.1 Per-article counts'!$A$2:$A$48,$B5)/SUMIFS('S3.1 Per-article counts'!$D$2:$D$48,'S3.1 Per-article counts'!$A$2:$A$48,$B5),"0.0%")&")"&IF(COUNTIFS('S3.1 Per-article counts'!$A$2:$A$48,$B5,'S3.1 Per-article counts'!$D$2:$D$48,">0")<5," [k="&COUNTIFS('S3.1 Per-article counts'!$A$2:$A$48,$B5,'S3.1 Per-article counts'!$D$2:$D$48,">0")&"/5]",""))) -> 25/44 (56.8%) | E5: =IF(COUNTIFS('S3.1 Per-article counts'!$A$2:$A$48,$B5,'S3.1 Per-article counts'!$E$2:$E$48,"NS")>0,"Not supported",IF(SUMIFS('S3.1 Per-article counts'!$F$2:$F$48,'S3.1 Per-article counts'!$A$2:$A$48,$B5)=0,"Not scored",SUMIFS('S3.1 Per-article counts'!$E$2:$E$48,'S3.1 Per-article counts'!$A$2:$A$48,$B5)&"/"&SUMIFS('S3.1 Per-article counts'!$F$2:$F$48,'S3.1 Per-article counts'!$A$2:$A$48,$B5)&" ("&TEXT(SUMIFS('S3.1 Per-article counts'!$E$2:$E$48,'S3.1 Per-article counts'!$A$2:$A$48,$B5)/SUMIFS('S3.1 Per-article counts'!$F$2:$F$48,'S3.1 Per-article counts'!$A$2:$A$48,$B5),"0.0%")&")"&IF(COUNTIFS('S3.1 Per-article counts'!$A$2:$A$48,$B5,'S3.1 Per-article counts'!$F$2:$F$48,">0")<5," [k="&COUNTIFS('S3.1 Per-article counts'!$A$2:$A$48,$B5,'S3.1 Per-article counts'!$F$2:$F$48,">0")&"/5]",""))) -> 5/44 (11.4%) | F5: =IF(COUNTIFS('S3.1 Per-article counts'!$A$2:$A$48,$B5,'S3.1 Per-article counts'!$G$2:$G$48,"NS")>0,"Not supported",IF(SUMIFS('S3.1 Per-article counts'!$H$2:$H$48,'S3.1 Per-article counts'!$A$2:$A$48,$B5)=0,"Not scored",SUMIFS('S3.1 Per-article counts'!$G$2:$G$48,'S3.1 Per-article counts'!$A$2:$A$48,$B5)&"/"&SUMIFS('S3.1 Per-article counts'!$H$2:$H$48,'S3.1 Per-article counts'!$A$2:$A$48,$B5)&" ("&TEXT(SUMIFS('S3.1 Per-article counts'!$G$2:$G$48,'S3.1 Per-article counts'!$A$2:$A$48,$B5)/SUMIFS('S3.1 Per-article counts'!$H$2:$H$48,'S3.1 Per-article counts'!$A$2:$A$48,$B5),"0.0%")&")"&IF(COUNTIFS('S3.1 Per-article counts'!$A$2:$A$48,$B5,'S3.1 Per-article counts'!$H$2:$H$48,">0")<5," [k="&COUNTIFS('S3.1 Per-article counts'!$A$2:$A$48,$B5,'S3.1 Per-article counts'!$H$2:$H$48,">0")&"/5]",""))) -> Not scored | G5: =IF(COUNTIFS('S3.1 Per-article counts'!$A$2:$A$48,$B5,'S3.1 Per-article counts'!$I$2:$I$48,"NS")>0,"Not supported",IF(SUMIFS('S3.1 Per-article counts'!$J$2:$J$48,'S3.1 Per-article counts'!$A$2:$A$48,$B5)=0,"Not scored",SUMIFS('S3.1 Per-article counts'!$I$2:$I$48,'S3.1 Per-article counts'!$A$2:$A$48,$B5)&"/"&SUMIFS('S3.1 Per-article counts'!$J$2:$J$48,'S3.1 Per-article counts'!$A$2:$A$48,$B5)&" ("&TEXT(SUMIFS('S3.1 Per-article counts'!$I$2:$I$48,'S3.1 Per-article counts'!$A$2:$A$48,$B5)/SUMIFS('S3.1 Per-article counts'!$J$2:$J$48,'S3.1 Per-article counts'!$A$2:$A$48,$B5),"0.0%")&")"&IF(COUNTIFS('S3.1 Per-article counts'!$A$2:$A$48,$B5,'S3.1 Per-article counts'!$J$2:$J$48,">0")<5," [k="&COUNTIFS('S3.1 Per-article counts'!$A$2:$A$48,$B5,'S3.1 Per-article counts'!$J$2:$J$48,">0")&"/5]",""))) -> 5/17 (29.4%) [k=2/5] | H5: =IF(COUNTIFS('S3.1 Per-article counts'!$A$2:$A$48,$B5,'S3.1 Per-article counts'!$K$2:$K$48,"NS")>0,"Not supported",IF(SUMIFS('S3.1 Per-article counts'!$L$2:$L$48,'S3.1 Per-article counts'!$A$2:$A$48,$B5)=0,"Not scored",SUMIFS('S3.1 Per-article counts'!$K$2:$K$48,'S3.1 Per-article counts'!$A$2:$A$48,$B5)&"/"&SUMIFS('S3.1 Per-article counts'!$L$2:$L$48,'S3.1 Per-article counts'!$A$2:$A$48,$B5)&" ("&TEXT(SUMIFS('S3.1 Per-article counts'!$K$2:$K$48,'S3.1 Per-article counts'!$A$2:$A$48,$B5)/SUMIFS('S3.1 Per-article counts'!$L$2:$L$48,'S3.1 Per-article counts'!$A$2:$A$48,$B5),"0.0%")&")"&IF(COUNTIFS('S3.1 Per-article counts'!$A$2:$A$48,$B5,'S3.1 Per-article counts'!$L$2:$L$48,">0")<5," [k="&COUNTIFS('S3.1 Per-article counts'!$A$2:$A$48,$B5,'S3.1 Per-article counts'!$L$2:$L$48,">0")&"/5]",""))) -> Not supported
A6: B. Tables | B6: Table coverage | C6: Numbered tables whose data content is retained / numbered tables | D6: =IF(COUNTIFS('S3.1 Per-article counts'!$A$2:$A$48,$B6,'S3.1 Per-article counts'!$C$2:$C$48,"NS")>0,"Not supported",IF(SUMIFS('S3.1 Per-article counts'!$D$2:$D$48,'S3.1 Per-article counts'!$A$2:$A$48,$B6)=0,"Not scored",SUMIFS('S3.1 Per-article counts'!$C$2:$C$48,'S3.1 Per-article counts'!$A$2:$A$48,$B6)&"/"&SUMIFS('S3.1 Per-article counts'!$D$2:$D$48,'S3.1 Per-article counts'!$A$2:$A$48,$B6)&" ("&TEXT(SUMIFS('S3.1 Per-article counts'!$C$2:$C$48,'S3.1 Per-article counts'!$A$2:$A$48,$B6)/SUMIFS('S3.1 Per-article counts'!$D$2:$D$48,'S3.1 Per-article counts'!$A$2:$A$48,$B6),"0.0%")&")"&IF(COUNTIFS('S3.1 Per-article counts'!$A$2:$A$48,$B6,'S3.1 Per-article counts'!$D$2:$D$48,">0")<5," [k="&COUNTIFS('S3.1 Per-article counts'!$A$2:$A$48,$B6,'S3.1 Per-article counts'!$D$2:$D$48,">0")&"/5]",""))) -> 12/12 (100.0%) | E6: =IF(COUNTIFS('S3.1 Per-article counts'!$A$2:$A$48,$B6,'S3.1 Per-article counts'!$E$2:$E$48,"NS")>0,"Not supported",IF(SUMIFS('S3.1 Per-article counts'!$F$2:$F$48,'S3.1 Per-article counts'!$A$2:$A$48,$B6)=0,"Not scored",SUMIFS('S3.1 Per-article counts'!$E$2:$E$48,'S3.1 Per-article counts'!$A$2:$A$48,$B6)&"/"&SUMIFS('S3.1 Per-article counts'!$F$2:$F$48,'S3.1 Per-article counts'!$A$2:$A$48,$B6)&" ("&TEXT(SUMIFS('S3.1 Per-article counts'!$E$2:$E$48,'S3.1 Per-article counts'!$A$2:$A$48,$B6)/SUMIFS('S3.1 Per-article counts'!$F$2:$F$48,'S3.1 Per-article counts'!$A$2:$A$48,$B6),"0.0%")&")"&IF(COUNTIFS('S3.1 Per-article counts'!$A$2:$A$48,$B6,'S3.1 Per-article counts'!$F$2:$F$48,">0")<5," [k="&COUNTIFS('S3.1 Per-article counts'!$A$2:$A$48,$B6,'S3.1 Per-article counts'!$F$2:$F$48,">0")&"/5]",""))) -> 11/12 (91.7%) | F6: =IF(COUNTIFS('S3.1 Per-article counts'!$A$2:$A$48,$B6,'S3.1 Per-article counts'!$G$2:$G$48,"NS")>0,"Not supported",IF(SUMIFS('S3.1 Per-article counts'!$H$2:$H$48,'S3.1 Per-article counts'!$A$2:$A$48,$B6)=0,"Not scored",SUMIFS('S3.1 Per-article counts'!$G$2:$G$48,'S3.1 Per-article counts'!$A$2:$A$48,$B6)&"/"&SUMIFS('S3.1 Per-article counts'!$H$2:$H$48,'S3.1 Per-article counts'!$A$2:$A$48,$B6)&" ("&TEXT(SUMIFS('S3.1 Per-article counts'!$G$2:$G$48,'S3.1 Per-article counts'!$A$2:$A$48,$B6)/SUMIFS('S3.1 Per-article counts'!$H$2:$H$48,'S3.1 Per-article counts'!$A$2:$A$48,$B6),"0.0%")&")"&IF(COUNTIFS('S3.1 Per-article counts'!$A$2:$A$48,$B6,'S3.1 Per-article counts'!$H$2:$H$48,">0")<5," [k="&COUNTIFS('S3.1 Per-article counts'!$A$2:$A$48,$B6,'S3.1 Per-article counts'!$H$2:$H$48,">0")&"/5]",""))) -> 12/12 (100.0%) | G6: =IF(COUNTIFS('S3.1 Per-article counts'!$A$2:$A$48,$B6,'S3.1 Per-article counts'!$I$2:$I$48,"NS")>0,"Not supported",IF(SUMIFS('S3.1 Per-article counts'!$J$2:$J$48,'S3.1 Per-article counts'!$A$2:$A$48,$B6)=0,"Not scored",SUMIFS('S3.1 Per-article counts'!$I$2:$I$48,'S3.1 Per-article counts'!$A$2:$A$48,$B6)&"/"&SUMIFS('S3.1 Per-article counts'!$J$2:$J$48,'S3.1 Per-article counts'!$A$2:$A$48,$B6)&" ("&TEXT(SUMIFS('S3.1 Per-article counts'!$I$2:$I$48,'S3.1 Per-article counts'!$A$2:$A$48,$B6)/SUMIFS('S3.1 Per-article counts'!$J$2:$J$48,'S3.1 Per-article counts'!$A$2:$A$48,$B6),"0.0%")&")"&IF(COUNTIFS('S3.1 Per-article counts'!$A$2:$A$48,$B6,'S3.1 Per-article counts'!$J$2:$J$48,">0")<5," [k="&COUNTIFS('S3.1 Per-article counts'!$A$2:$A$48,$B6,'S3.1 Per-article counts'!$J$2:$J$48,">0")&"/5]",""))) -> 8/10 (80.0%) [k=4/5] | H6: =IF(COUNTIFS('S3.1 Per-article counts'!$A$2:$A$48,$B6,'S3.1 Per-article counts'!$K$2:$K$48,"NS")>0,"Not supported",IF(SUMIFS('S3.1 Per-article counts'!$L$2:$L$48,'S3.1 Per-article counts'!$A$2:$A$48,$B6)=0,"Not scored",SUMIFS('S3.1 Per-article counts'!$K$2:$K$48,'S3.1 Per-article counts'!$A$2:$A$48,$B6)&"/"&SUMIFS('S3.1 Per-article counts'!$L$2:$L$48,'S3.1 Per-article counts'!$A$2:$A$48,$B6)&" ("&TEXT(SUMIFS('S3.1 Per-article counts'!$K$2:$K$48,'S3.1 Per-article counts'!$A$2:$A$48,$B6)/SUMIFS('S3.1 Per-article counts'!$L$2:$L$48,'S3.1 Per-article counts'!$A$2:$A$48,$B6),"0.0%")&")"&IF(COUNTIFS('S3.1 Per-article counts'!$A$2:$A$48,$B6,'S3.1 Per-article counts'!$L$2:$L$48,">0")<5," [k="&COUNTIFS('S3.1 Per-article counts'!$A$2:$A$48,$B6,'S3.1 Per-article counts'!$L$2:$L$48,">0")&"/5]",""))) -> 10/12 (83.3%)
A7: B. Tables | B7: Basic table structure | C7: Tables with identifiable rows and columns / numbered tables | D7: =IF(COUNTIFS('S3.1 Per-article counts'!$A$2:$A$48,$B7,'S3.1 Per-article counts'!$C$2:$C$48,"NS")>0,"Not supported",IF(SUMIFS('S3.1 Per-article counts'!$D$2:$D$48,'S3.1 Per-article counts'!$A$2:$A$48,$B7)=0,"Not scored",SUMIFS('S3.1 Per-article counts'!$C$2:$C$48,'S3.1 Per-article counts'!$A$2:$A$48,$B7)&"/"&SUMIFS('S3.1 Per-article counts'!$D$2:$D$48,'S3.1 Per-article counts'!$A$2:$A$48,$B7)&" ("&TEXT(SUMIFS('S3.1 Per-article counts'!$C$2:$C$48,'S3.1 Per-article counts'!$A$2:$A$48,$B7)/SUMIFS('S3.1 Per-article counts'!$D$2:$D$48,'S3.1 Per-article counts'!$A$2:$A$48,$B7),"0.0%")&")"&IF(COUNTIFS('S3.1 Per-article counts'!$A$2:$A$48,$B7,'S3.1 Per-article counts'!$D$2:$D$48,">0")<5," [k="&COUNTIFS('S3.1 Per-article counts'!$A$2:$A$48,$B7,'S3.1 Per-article counts'!$D$2:$D$48,">0")&"/5]",""))) -> 10/12 (83.3%) | E7: =IF(COUNTIFS('S3.1 Per-article counts'!$A$2:$A$48,$B7,'S3.1 Per-article counts'!$E$2:$E$48,"NS")>0,"Not supported",IF(SUMIFS('S3.1 Per-article counts'!$F$2:$F$48,'S3.1 Per-article counts'!$A$2:$A$48,$B7)=0,"Not scored",SUMIFS('S3.1 Per-article counts'!$E$2:$E$48,'S3.1 Per-article counts'!$A$2:$A$48,$B7)&"/"&SUMIFS('S3.1 Per-article counts'!$F$2:$F$48,'S3.1 Per-article counts'!$A$2:$A$48,$B7)&" ("&TEXT(SUMIFS('S3.1 Per-article counts'!$E$2:$E$48,'S3.1 Per-article counts'!$A$2:$A$48,$B7)/SUMIFS('S3.1 Per-article counts'!$F$2:$F$48,'S3.1 Per-article counts'!$A$2:$A$48,$B7),"0.0%")&")"&IF(COUNTIFS('S3.1 Per-article counts'!$A$2:$A$48,$B7,'S3.1 Per-article counts'!$F$2:$F$48,">0")<5," [k="&COUNTIFS('S3.1 Per-article counts'!$A$2:$A$48,$B7,'S3.1 Per-article counts'!$F$2:$F$48,">0")&"/5]",""))) -> 7/12 (58.3%) | F7: =IF(COUNTIFS('S3.1 Per-article counts'!$A$2:$A$48,$B7,'S3.1 Per-article counts'!$G$2:$G$48,"NS")>0,"Not supported",IF(SUMIFS('S3.1 Per-article counts'!$H$2:$H$48,'S3.1 Per-article counts'!$A$2:$A$48,$B7)=0,"Not scored",SUMIFS('S3.1 Per-article counts'!$G$2:$G$48,'S3.1 Per-article counts'!$A$2:$A$48,$B7)&"/"&SUMIFS('S3.1 Per-article counts'!$H$2:$H$48,'S3.1 Per-article counts'!$A$2:$A$48,$B7)&" ("&TEXT(SUMIFS('S3.1 Per-article counts'!$G$2:$G$48,'S3.1 Per-article counts'!$A$2:$A$48,$B7)/SUMIFS('S3.1 Per-article counts'!$H$2:$H$48,'S3.1 Per-article counts'!$A$2:$A$48,$B7),"0.0%")&")"&IF(COUNTIFS('S3.1 Per-article counts'!$A$2:$A$48,$B7,'S3.1 Per-article counts'!$H$2:$H$48,">0")<5," [k="&COUNTIFS('S3.1 Per-article counts'!$A$2:$A$48,$B7,'S3.1 Per-article counts'!$H$2:$H$48,">0")&"/5]",""))) -> 9/12 (75.0%) | G7: =IF(COUNTIFS('S3.1 Per-article counts'!$A$2:$A$48,$B7,'S3.1 Per-article counts'!$I$2:$I$48,"NS")>0,"Not supported",IF(SUMIFS('S3.1 Per-article counts'!$J$2:$J$48,'S3.1 Per-article counts'!$A$2:$A$48,$B7)=0,"Not scored",SUMIFS('S3.1 Per-article counts'!$I$2:$I$48,'S3.1 Per-article counts'!$A$2:$A$48,$B7)&"/"&SUMIFS('S3.1 Per-article counts'!$J$2:$J$48,'S3.1 Per-article counts'!$A$2:$A$48,$B7)&" ("&TEXT(SUMIFS('S3.1 Per-article counts'!$I$2:$I$48,'S3.1 Per-article counts'!$A$2:$A$48,$B7)/SUMIFS('S3.1 Per-article counts'!$J$2:$J$48,'S3.1 Per-article counts'!$A$2:$A$48,$B7),"0.0%")&")"&IF(COUNTIFS('S3.1 Per-article counts'!$A$2:$A$48,$B7,'S3.1 Per-article counts'!$J$2:$J$48,">0")<5," [k="&COUNTIFS('S3.1 Per-article counts'!$A$2:$A$48,$B7,'S3.1 Per-article counts'!$J$2:$J$48,">0")&"/5]",""))) -> 7/10 (70.0%) [k=4/5] | H7: =IF(COUNTIFS('S3.1 Per-article counts'!$A$2:$A$48,$B7,'S3.1 Per-article counts'!$K$2:$K$48,"NS")>0,"Not supported",IF(SUMIFS('S3.1 Per-article counts'!$L$2:$L$48,'S3.1 Per-article counts'!$A$2:$A$48,$B7)=0,"Not scored",SUMIFS('S3.1 Per-article counts'!$K$2:$K$48,'S3.1 Per-article counts'!$A$2:$A$48,$B7)&"/"&SUMIFS('S3.1 Per-article counts'!$L$2:$L$48,'S3.1 Per-article counts'!$A$2:$A$48,$B7)&" ("&TEXT(SUMIFS('S3.1 Per-article counts'!$K$2:$K$48,'S3.1 Per-article counts'!$A$2:$A$48,$B7)/SUMIFS('S3.1 Per-article counts'!$L$2:$L$48,'S3.1 Per-article counts'!$A$2:$A$48,$B7),"0.0%")&")"&IF(COUNTIFS('S3.1 Per-article counts'!$A$2:$A$48,$B7,'S3.1 Per-article counts'!$L$2:$L$48,">0")<5," [k="&COUNTIFS('S3.1 Per-article counts'!$A$2:$A$48,$B7,'S3.1 Per-article counts'!$L$2:$L$48,">0")&"/5]",""))) -> 4/12 (33.3%)
A8: B. Tables | B8: Table header hierarchy | C8: Tables with nested headers whose parent-child relations are correct / tables with nested headers | D8: =IF(COUNTIFS('S3.1 Per-article counts'!$A$2:$A$48,$B8,'S3.1 Per-article counts'!$C$2:$C$48,"NS")>0,"Not supported",IF(SUMIFS('S3.1 Per-article counts'!$D$2:$D$48,'S3.1 Per-article counts'!$A$2:$A$48,$B8)=0,"Not scored",SUMIFS('S3.1 Per-article counts'!$C$2:$C$48,'S3.1 Per-article counts'!$A$2:$A$48,$B8)&"/"&SUMIFS('S3.1 Per-article counts'!$D$2:$D$48,'S3.1 Per-article counts'!$A$2:$A$48,$B8)&" ("&TEXT(SUMIFS('S3.1 Per-article counts'!$C$2:$C$48,'S3.1 Per-article counts'!$A$2:$A$48,$B8)/SUMIFS('S3.1 Per-article counts'!$D$2:$D$48,'S3.1 Per-article counts'!$A$2:$A$48,$B8),"0.0%")&")"&IF(COUNTIFS('S3.1 Per-article counts'!$A$2:$A$48,$B8,'S3.1 Per-article counts'!$D$2:$D$48,">0")<3," [k="&COUNTIFS('S3.1 Per-article counts'!$A$2:$A$48,$B8,'S3.1 Per-article counts'!$D$2:$D$48,">0")&"/3]",""))) -> 4/6 (66.7%) | E8: =IF(COUNTIFS('S3.1 Per-article counts'!$A$2:$A$48,$B8,'S3.1 Per-article counts'!$E$2:$E$48,"NS")>0,"Not supported",IF(SUMIFS('S3.1 Per-article counts'!$F$2:$F$48,'S3.1 Per-article counts'!$A$2:$A$48,$B8)=0,"Not scored",SUMIFS('S3.1 Per-article counts'!$E$2:$E$48,'S3.1 Per-article counts'!$A$2:$A$48,$B8)&"/"&SUMIFS('S3.1 Per-article counts'!$F$2:$F$48,'S3.1 Per-article counts'!$A$2:$A$48,$B8)&" ("&TEXT(SUMIFS('S3.1 Per-article counts'!$E$2:$E$48,'S3.1 Per-article counts'!$A$2:$A$48,$B8)/SUMIFS('S3.1 Per-article counts'!$F$2:$F$48,'S3.1 Per-article counts'!$A$2:$A$48,$B8),"0.0%")&")"&IF(COUNTIFS('S3.1 Per-article counts'!$A$2:$A$48,$B8,'S3.1 Per-article counts'!$F$2:$F$48,">0")<3," [k="&COUNTIFS('S3.1 Per-article counts'!$A$2:$A$48,$B8,'S3.1 Per-article counts'!$F$2:$F$48,">0")&"/3]",""))) -> 2/6 (33.3%) | F8: =IF(COUNTIFS('S3.1 Per-article counts'!$A$2:$A$48,$B8,'S3.1 Per-article counts'!$G$2:$G$48,"NS")>0,"Not supported",IF(SUMIFS('S3.1 Per-article counts'!$H$2:$H$48,'S3.1 Per-article counts'!$A$2:$A$48,$B8)=0,"Not scored",SUMIFS('S3.1 Per-article counts'!$G$2:$G$48,'S3.1 Per-article counts'!$A$2:$A$48,$B8)&"/"&SUMIFS('S3.1 Per-article counts'!$H$2:$H$48,'S3.1 Per-article counts'!$A$2:$A$48,$B8)&" ("&TEXT(SUMIFS('S3.1 Per-article counts'!$G$2:$G$48,'S3.1 Per-article counts'!$A$2:$A$48,$B8)/SUMIFS('S3.1 Per-article counts'!$H$2:$H$48,'S3.1 Per-article counts'!$A$2:$A$48,$B8),"0.0%")&")"&IF(COUNTIFS('S3.1 Per-article counts'!$A$2:$A$48,$B8,'S3.1 Per-article counts'!$H$2:$H$48,">0")<3," [k="&COUNTIFS('S3.1 Per-article counts'!$A$2:$A$48,$B8,'S3.1 Per-article counts'!$H$2:$H$48,">0")&"/3]",""))) -> 3/6 (50.0%) | G8: =IF(COUNTIFS('S3.1 Per-article counts'!$A$2:$A$48,$B8,'S3.1 Per-article counts'!$I$2:$I$48,"NS")>0,"Not supported",IF(SUMIFS('S3.1 Per-article counts'!$J$2:$J$48,'S3.1 Per-article counts'!$A$2:$A$48,$B8)=0,"Not scored",SUMIFS('S3.1 Per-article counts'!$I$2:$I$48,'S3.1 Per-article counts'!$A$2:$A$48,$B8)&"/"&SUMIFS('S3.1 Per-article counts'!$J$2:$J$48,'S3.1 Per-article counts'!$A$2:$A$48,$B8)&" ("&TEXT(SUMIFS('S3.1 Per-article counts'!$I$2:$I$48,'S3.1 Per-article counts'!$A$2:$A$48,$B8)/SUMIFS('S3.1 Per-article counts'!$J$2:$J$48,'S3.1 Per-article counts'!$A$2:$A$48,$B8),"0.0%")&")"&IF(COUNTIFS('S3.1 Per-article counts'!$A$2:$A$48,$B8,'S3.1 Per-article counts'!$J$2:$J$48,">0")<3," [k="&COUNTIFS('S3.1 Per-article counts'!$A$2:$A$48,$B8,'S3.1 Per-article counts'!$J$2:$J$48,">0")&"/3]",""))) -> 3/5 (60.0%) [k=2/3] | H8: =IF(COUNTIFS('S3.1 Per-article counts'!$A$2:$A$48,$B8,'S3.1 Per-article counts'!$K$2:$K$48,"NS")>0,"Not supported",IF(SUMIFS('S3.1 Per-article counts'!$L$2:$L$48,'S3.1 Per-article counts'!$A$2:$A$48,$B8)=0,"Not scored",SUMIFS('S3.1 Per-article counts'!$K$2:$K$48,'S3.1 Per-article counts'!$A$2:$A$48,$B8)&"/"&SUMIFS('S3.1 Per-article counts'!$L$2:$L$48,'S3.1 Per-article counts'!$A$2:$A$48,$B8)&" ("&TEXT(SUMIFS('S3.1 Per-article counts'!$K$2:$K$48,'S3.1 Per-article counts'!$A$2:$A$48,$B8)/SUMIFS('S3.1 Per-article counts'!$L$2:$L$48,'S3.1 Per-article counts'!$A$2:$A$48,$B8),"0.0%")&")"&IF(COUNTIFS('S3.1 Per-article counts'!$A$2:$A$48,$B8,'S3.1 Per-article counts'!$L$2:$L$48,">0")<3," [k="&COUNTIFS('S3.1 Per-article counts'!$A$2:$A$48,$B8,'S3.1 Per-article counts'!$L$2:$L$48,">0")&"/3]",""))) -> 0/6 (0.0%)
A9: B. Tables | B9: Table numerical fidelity | C9: Correctly transcribed numerical entries / reference entries | D9: =IF(COUNTIFS('S3.1 Per-article counts'!$A$2:$A$48,$B9,'S3.1 Per-article counts'!$C$2:$C$48,"NS")>0,"Not supported",IF(SUMIFS('S3.1 Per-article counts'!$D$2:$D$48,'S3.1 Per-article counts'!$A$2:$A$48,$B9)=0,"Not scored",SUMIFS('S3.1 Per-article counts'!$C$2:$C$48,'S3.1 Per-article counts'!$A$2:$A$48,$B9)&"/"&SUMIFS('S3.1 Per-article counts'!$D$2:$D$48,'S3.1 Per-article counts'!$A$2:$A$48,$B9)&" ("&TEXT(SUMIFS('S3.1 Per-article counts'!$C$2:$C$48,'S3.1 Per-article counts'!$A$2:$A$48,$B9)/SUMIFS('S3.1 Per-article counts'!$D$2:$D$48,'S3.1 Per-article counts'!$A$2:$A$48,$B9),"0.0%")&")"&IF(COUNTIFS('S3.1 Per-article counts'!$A$2:$A$48,$B9,'S3.1 Per-article counts'!$D$2:$D$48,">0")<5," [k="&COUNTIFS('S3.1 Per-article counts'!$A$2:$A$48,$B9,'S3.1 Per-article counts'!$D$2:$D$48,">0")&"/5]",""))) -> 297/312 (95.2%) | E9: =IF(COUNTIFS('S3.1 Per-article counts'!$A$2:$A$48,$B9,'S3.1 Per-article counts'!$E$2:$E$48,"NS")>0,"Not supported",IF(SUMIFS('S3.1 Per-article counts'!$F$2:$F$48,'S3.1 Per-article counts'!$A$2:$A$48,$B9)=0,"Not scored",SUMIFS('S3.1 Per-article counts'!$E$2:$E$48,'S3.1 Per-article counts'!$A$2:$A$48,$B9)&"/"&SUMIFS('S3.1 Per-article counts'!$F$2:$F$48,'S3.1 Per-article counts'!$A$2:$A$48,$B9)&" ("&TEXT(SUMIFS('S3.1 Per-article counts'!$E$2:$E$48,'S3.1 Per-article counts'!$A$2:$A$48,$B9)/SUMIFS('S3.1 Per-article counts'!$F$2:$F$48,'S3.1 Per-article counts'!$A$2:$A$48,$B9),"0.0%")&")"&IF(COUNTIFS('S3.1 Per-article counts'!$A$2:$A$48,$B9,'S3.1 Per-article counts'!$F$2:$F$48,">0")<5," [k="&COUNTIFS('S3.1 Per-article counts'!$A$2:$A$48,$B9,'S3.1 Per-article counts'!$F$2:$F$48,">0")&"/5]",""))) -> 279/312 (89.4%) | F9: =IF(COUNTIFS('S3.1 Per-article counts'!$A$2:$A$48,$B9,'S3.1 Per-article counts'!$G$2:$G$48,"NS")>0,"Not supported",IF(SUMIFS('S3.1 Per-article counts'!$H$2:$H$48,'S3.1 Per-article counts'!$A$2:$A$48,$B9)=0,"Not scored",SUMIFS('S3.1 Per-article counts'!$G$2:$G$48,'S3.1 Per-article counts'!$A$2:$A$48,$B9)&"/"&SUMIFS('S3.1 Per-article counts'!$H$2:$H$48,'S3.1 Per-article counts'!$A$2:$A$48,$B9)&" ("&TEXT(SUMIFS('S3.1 Per-article counts'!$G$2:$G$48,'S3.1 Per-article counts'!$A$2:$A$48,$B9)/SUMIFS('S3.1 Per-article counts'!$H$2:$H$48,'S3.1 Per-article counts'!$A$2:$A$48,$B9),"0.0%")&")"&IF(COUNTIFS('S3.1 Per-article counts'!$A$2:$A$48,$B9,'S3.1 Per-article counts'!$H$2:$H$48,">0")<5," [k="&COUNTIFS('S3.1 Per-article counts'!$A$2:$A$48,$B9,'S3.1 Per-article counts'!$H$2:$H$48,">0")&"/5]",""))) -> 312/312 (100.0%) | G9: =IF(COUNTIFS('S3.1 Per-article counts'!$A$2:$A$48,$B9,'S3.1 Per-article counts'!$I$2:$I$48,"NS")>0,"Not supported",IF(SUMIFS('S3.1 Per-article counts'!$J$2:$J$48,'S3.1 Per-article counts'!$A$2:$A$48,$B9)=0,"Not scored",SUMIFS('S3.1 Per-article counts'!$I$2:$I$48,'S3.1 Per-article counts'!$A$2:$A$48,$B9)&"/"&SUMIFS('S3.1 Per-article counts'!$J$2:$J$48,'S3.1 Per-article counts'!$A$2:$A$48,$B9)&" ("&TEXT(SUMIFS('S3.1 Per-article counts'!$I$2:$I$48,'S3.1 Per-article counts'!$A$2:$A$48,$B9)/SUMIFS('S3.1 Per-article counts'!$J$2:$J$48,'S3.1 Per-article counts'!$A$2:$A$48,$B9),"0.0%")&")"&IF(COUNTIFS('S3.1 Per-article counts'!$A$2:$A$48,$B9,'S3.1 Per-article counts'!$J$2:$J$48,">0")<5," [k="&COUNTIFS('S3.1 Per-article counts'!$A$2:$A$48,$B9,'S3.1 Per-article counts'!$J$2:$J$48,">0")&"/5]",""))) -> 141/252 (56.0%) [k=3/5] | H9: =IF(COUNTIFS('S3.1 Per-article counts'!$A$2:$A$48,$B9,'S3.1 Per-article counts'!$K$2:$K$48,"NS")>0,"Not supported",IF(SUMIFS('S3.1 Per-article counts'!$L$2:$L$48,'S3.1 Per-article counts'!$A$2:$A$48,$B9)=0,"Not scored",SUMIFS('S3.1 Per-article counts'!$K$2:$K$48,'S3.1 Per-article counts'!$A$2:$A$48,$B9)&"/"&SUMIFS('S3.1 Per-article counts'!$L$2:$L$48,'S3.1 Per-article counts'!$A$2:$A$48,$B9)&" ("&TEXT(SUMIFS('S3.1 Per-article counts'!$K$2:$K$48,'S3.1 Per-article counts'!$A$2:$A$48,$B9)/SUMIFS('S3.1 Per-article counts'!$L$2:$L$48,'S3.1 Per-article counts'!$A$2:$A$48,$B9),"0.0%")&")"&IF(COUNTIFS('S3.1 Per-article counts'!$A$2:$A$48,$B9,'S3.1 Per-article counts'!$L$2:$L$48,">0")<5," [k="&COUNTIFS('S3.1 Per-article counts'!$A$2:$A$48,$B9,'S3.1 Per-article counts'!$L$2:$L$48,">0")&"/5]",""))) -> 280/312 (89.7%)
A10: B. Tables | B10: Numerical-context preservation | C10: Values bound to correct row/column label, unit and ± or range (strict label matching) / values checked | D10: =IF(COUNTIFS('S3.1 Per-article counts'!$A$2:$A$48,$B10,'S3.1 Per-article counts'!$C$2:$C$48,"NS")>0,"Not supported",IF(SUMIFS('S3.1 Per-article counts'!$D$2:$D$48,'S3.1 Per-article counts'!$A$2:$A$48,$B10)=0,"Not scored",SUMIFS('S3.1 Per-article counts'!$C$2:$C$48,'S3.1 Per-article counts'!$A$2:$A$48,$B10)&"/"&SUMIFS('S3.1 Per-article counts'!$D$2:$D$48,'S3.1 Per-article counts'!$A$2:$A$48,$B10)&" ("&TEXT(SUMIFS('S3.1 Per-article counts'!$C$2:$C$48,'S3.1 Per-article counts'!$A$2:$A$48,$B10)/SUMIFS('S3.1 Per-article counts'!$D$2:$D$48,'S3.1 Per-article counts'!$A$2:$A$48,$B10),"0.0%")&")"&IF(COUNTIFS('S3.1 Per-article counts'!$A$2:$A$48,$B10,'S3.1 Per-article counts'!$D$2:$D$48,">0")<4," [k="&COUNTIFS('S3.1 Per-article counts'!$A$2:$A$48,$B10,'S3.1 Per-article counts'!$D$2:$D$48,">0")&"/4]",""))) -> 164/164 (100.0%) | E10: =IF(COUNTIFS('S3.1 Per-article counts'!$A$2:$A$48,$B10,'S3.1 Per-article counts'!$E$2:$E$48,"NS")>0,"Not supported",IF(SUMIFS('S3.1 Per-article counts'!$F$2:$F$48,'S3.1 Per-article counts'!$A$2:$A$48,$B10)=0,"Not scored",SUMIFS('S3.1 Per-article counts'!$E$2:$E$48,'S3.1 Per-article counts'!$A$2:$A$48,$B10)&"/"&SUMIFS('S3.1 Per-article counts'!$F$2:$F$48,'S3.1 Per-article counts'!$A$2:$A$48,$B10)&" ("&TEXT(SUMIFS('S3.1 Per-article counts'!$E$2:$E$48,'S3.1 Per-article counts'!$A$2:$A$48,$B10)/SUMIFS('S3.1 Per-article counts'!$F$2:$F$48,'S3.1 Per-article counts'!$A$2:$A$48,$B10),"0.0%")&")"&IF(COUNTIFS('S3.1 Per-article counts'!$A$2:$A$48,$B10,'S3.1 Per-article counts'!$F$2:$F$48,">0")<4," [k="&COUNTIFS('S3.1 Per-article counts'!$A$2:$A$48,$B10,'S3.1 Per-article counts'!$F$2:$F$48,">0")&"/4]",""))) -> 142/164 (86.6%) | F10: =IF(COUNTIFS('S3.1 Per-article counts'!$A$2:$A$48,$B10,'S3.1 Per-article counts'!$G$2:$G$48,"NS")>0,"Not supported",IF(SUMIFS('S3.1 Per-article counts'!$H$2:$H$48,'S3.1 Per-article counts'!$A$2:$A$48,$B10)=0,"Not scored",SUMIFS('S3.1 Per-article counts'!$G$2:$G$48,'S3.1 Per-article counts'!$A$2:$A$48,$B10)&"/"&SUMIFS('S3.1 Per-article counts'!$H$2:$H$48,'S3.1 Per-article counts'!$A$2:$A$48,$B10)&" ("&TEXT(SUMIFS('S3.1 Per-article counts'!$G$2:$G$48,'S3.1 Per-article counts'!$A$2:$A$48,$B10)/SUMIFS('S3.1 Per-article counts'!$H$2:$H$48,'S3.1 Per-article counts'!$A$2:$A$48,$B10),"0.0%")&")"&IF(COUNTIFS('S3.1 Per-article counts'!$A$2:$A$48,$B10,'S3.1 Per-article counts'!$H$2:$H$48,">0")<4," [k="&COUNTIFS('S3.1 Per-article counts'!$A$2:$A$48,$B10,'S3.1 Per-article counts'!$H$2:$H$48,">0")&"/4]",""))) -> 72/140 (51.4%) [k=3/4] | G10: =IF(COUNTIFS('S3.1 Per-article counts'!$A$2:$A$48,$B10,'S3.1 Per-article counts'!$I$2:$I$48,"NS")>0,"Not supported",IF(SUMIFS('S3.1 Per-article counts'!$J$2:$J$48,'S3.1 Per-article counts'!$A$2:$A$48,$B10)=0,"Not scored",SUMIFS('S3.1 Per-article counts'!$I$2:$I$48,'S3.1 Per-article counts'!$A$2:$A$48,$B10)&"/"&SUMIFS('S3.1 Per-article counts'!$J$2:$J$48,'S3.1 Per-article counts'!$A$2:$A$48,$B10)&" ("&TEXT(SUMIFS('S3.1 Per-article counts'!$I$2:$I$48,'S3.1 Per-article counts'!$A$2:$A$48,$B10)/SUMIFS('S3.1 Per-article counts'!$J$2:$J$48,'S3.1 Per-article counts'!$A$2:$A$48,$B10),"0.0%")&")"&IF(COUNTIFS('S3.1 Per-article counts'!$A$2:$A$48,$B10,'S3.1 Per-article counts'!$J$2:$J$48,">0")<4," [k="&COUNTIFS('S3.1 Per-article counts'!$A$2:$A$48,$B10,'S3.1 Per-article counts'!$J$2:$J$48,">0")&"/4]",""))) -> 139/164 (84.8%) | H10: =IF(COUNTIFS('S3.1 Per-article counts'!$A$2:$A$48,$B10,'S3.1 Per-article counts'!$K$2:$K$48,"NS")>0,"Not supported",IF(SUMIFS('S3.1 Per-article counts'!$L$2:$L$48,'S3.1 Per-article counts'!$A$2:$A$48,$B10)=0,"Not scored",SUMIFS('S3.1 Per-article counts'!$K$2:$K$48,'S3.1 Per-article counts'!$A$2:$A$48,$B10)&"/"&SUMIFS('S3.1 Per-article counts'!$L$2:$L$48,'S3.1 Per-article counts'!$A$2:$A$48,$B10)&" ("&TEXT(SUMIFS('S3.1 Per-article counts'!$K$2:$K$48,'S3.1 Per-article counts'!$A$2:$A$48,$B10)/SUMIFS('S3.1 Per-article counts'!$L$2:$L$48,'S3.1 Per-article counts'!$A$2:$A$48,$B10),"0.0%")&")"&IF(COUNTIFS('S3.1 Per-article counts'!$A$2:$A$48,$B10,'S3.1 Per-article counts'!$L$2:$L$48,">0")<4," [k="&COUNTIFS('S3.1 Per-article counts'!$A$2:$A$48,$B10,'S3.1 Per-article counts'!$L$2:$L$48,">0")&"/4]",""))) -> 0/21 (0.0%) [k=1/4]
A11: C. Figures and captions | B11: Figure visual preservation | C11: Figures retained with all recognisable panels / numbered figures | D11: =IF(COUNTIFS('S3.1 Per-article counts'!$A$2:$A$48,$B11,'S3.1 Per-article counts'!$C$2:$C$48,"NS")>0,"Not supported",IF(SUMIFS('S3.1 Per-article counts'!$D$2:$D$48,'S3.1 Per-article counts'!$A$2:$A$48,$B11)=0,"Not scored",SUMIFS('S3.1 Per-article counts'!$C$2:$C$48,'S3.1 Per-article counts'!$A$2:$A$48,$B11)&"/"&SUMIFS('S3.1 Per-article counts'!$D$2:$D$48,'S3.1 Per-article counts'!$A$2:$A$48,$B11)&" ("&TEXT(SUMIFS('S3.1 Per-article counts'!$C$2:$C$48,'S3.1 Per-article counts'!$A$2:$A$48,$B11)/SUMIFS('S3.1 Per-article counts'!$D$2:$D$48,'S3.1 Per-article counts'!$A$2:$A$48,$B11),"0.0%")&")"&IF(COUNTIFS('S3.1 Per-article counts'!$A$2:$A$48,$B11,'S3.1 Per-article counts'!$D$2:$D$48,">0")<5," [k="&COUNTIFS('S3.1 Per-article counts'!$A$2:$A$48,$B11,'S3.1 Per-article counts'!$D$2:$D$48,">0")&"/5]",""))) -> 31/32 (96.9%) | E11: =IF(COUNTIFS('S3.1 Per-article counts'!$A$2:$A$48,$B11,'S3.1 Per-article counts'!$E$2:$E$48,"NS")>0,"Not supported",IF(SUMIFS('S3.1 Per-article counts'!$F$2:$F$48,'S3.1 Per-article counts'!$A$2:$A$48,$B11)=0,"Not scored",SUMIFS('S3.1 Per-article counts'!$E$2:$E$48,'S3.1 Per-article counts'!$A$2:$A$48,$B11)&"/"&SUMIFS('S3.1 Per-article counts'!$F$2:$F$48,'S3.1 Per-article counts'!$A$2:$A$48,$B11)&" ("&TEXT(SUMIFS('S3.1 Per-article counts'!$E$2:$E$48,'S3.1 Per-article counts'!$A$2:$A$48,$B11)/SUMIFS('S3.1 Per-article counts'!$F$2:$F$48,'S3.1 Per-article counts'!$A$2:$A$48,$B11),"0.0%")&")"&IF(COUNTIFS('S3.1 Per-article counts'!$A$2:$A$48,$B11,'S3.1 Per-article counts'!$F$2:$F$48,">0")<5," [k="&COUNTIFS('S3.1 Per-article counts'!$A$2:$A$48,$B11,'S3.1 Per-article counts'!$F$2:$F$48,">0")&"/5]",""))) -> Not supported | F11: =IF(COUNTIFS('S3.1 Per-article counts'!$A$2:$A$48,$B11,'S3.1 Per-article counts'!$G$2:$G$48,"NS")>0,"Not supported",IF(SUMIFS('S3.1 Per-article counts'!$H$2:$H$48,'S3.1 Per-article counts'!$A$2:$A$48,$B11)=0,"Not scored",SUMIFS('S3.1 Per-article counts'!$G$2:$G$48,'S3.1 Per-article counts'!$A$2:$A$48,$B11)&"/"&SUMIFS('S3.1 Per-article counts'!$H$2:$H$48,'S3.1 Per-article counts'!$A$2:$A$48,$B11)&" ("&TEXT(SUMIFS('S3.1 Per-article counts'!$G$2:$G$48,'S3.1 Per-article counts'!$A$2:$A$48,$B11)/SUMIFS('S3.1 Per-article counts'!$H$2:$H$48,'S3.1 Per-article counts'!$A$2:$A$48,$B11),"0.0%")&")"&IF(COUNTIFS('S3.1 Per-article counts'!$A$2:$A$48,$B11,'S3.1 Per-article counts'!$H$2:$H$48,">0")<5," [k="&COUNTIFS('S3.1 Per-article counts'!$A$2:$A$48,$B11,'S3.1 Per-article counts'!$H$2:$H$48,">0")&"/5]",""))) -> 5/5 (100.0%) [k=1/5] | G11: =IF(COUNTIFS('S3.1 Per-article counts'!$A$2:$A$48,$B11,'S3.1 Per-article counts'!$I$2:$I$48,"NS")>0,"Not supported",IF(SUMIFS('S3.1 Per-article counts'!$J$2:$J$48,'S3.1 Per-article counts'!$A$2:$A$48,$B11)=0,"Not scored",SUMIFS('S3.1 Per-article counts'!$I$2:$I$48,'S3.1 Per-article counts'!$A$2:$A$48,$B11)&"/"&SUMIFS('S3.1 Per-article counts'!$J$2:$J$48,'S3.1 Per-article counts'!$A$2:$A$48,$B11)&" ("&TEXT(SUMIFS('S3.1 Per-article counts'!$I$2:$I$48,'S3.1 Per-article counts'!$A$2:$A$48,$B11)/SUMIFS('S3.1 Per-article counts'!$J$2:$J$48,'S3.1 Per-article counts'!$A$2:$A$48,$B11),"0.0%")&")"&IF(COUNTIFS('S3.1 Per-article counts'!$A$2:$A$48,$B11,'S3.1 Per-article counts'!$J$2:$J$48,">0")<5," [k="&COUNTIFS('S3.1 Per-article counts'!$A$2:$A$48,$B11,'S3.1 Per-article counts'!$J$2:$J$48,">0")&"/5]",""))) -> Not supported | H11: =IF(COUNTIFS('S3.1 Per-article counts'!$A$2:$A$48,$B11,'S3.1 Per-article counts'!$K$2:$K$48,"NS")>0,"Not supported",IF(SUMIFS('S3.1 Per-article counts'!$L$2:$L$48,'S3.1 Per-article counts'!$A$2:$A$48,$B11)=0,"Not scored",SUMIFS('S3.1 Per-article counts'!$K$2:$K$48,'S3.1 Per-article counts'!$A$2:$A$48,$B11)&"/"&SUMIFS('S3.1 Per-article counts'!$L$2:$L$48,'S3.1 Per-article counts'!$A$2:$A$48,$B11)&" ("&TEXT(SUMIFS('S3.1 Per-article counts'!$K$2:$K$48,'S3.1 Per-article counts'!$A$2:$A$48,$B11)/SUMIFS('S3.1 Per-article counts'!$L$2:$L$48,'S3.1 Per-article counts'!$A$2:$A$48,$B11),"0.0%")&")"&IF(COUNTIFS('S3.1 Per-article counts'!$A$2:$A$48,$B11,'S3.1 Per-article counts'!$L$2:$L$48,">0")<5," [k="&COUNTIFS('S3.1 Per-article counts'!$A$2:$A$48,$B11,'S3.1 Per-article counts'!$L$2:$L$48,">0")&"/5]",""))) -> Not supported
A12: C. Figures and captions | B12: Caption coverage | C12: Numbered captions retained / numbered captions (Tabula: table captions only) | D12: =IF(COUNTIFS('S3.1 Per-article counts'!$A$2:$A$48,$B12,'S3.1 Per-article counts'!$C$2:$C$48,"NS")>0,"Not supported",IF(SUMIFS('S3.1 Per-article counts'!$D$2:$D$48,'S3.1 Per-article counts'!$A$2:$A$48,$B12)=0,"Not scored",SUMIFS('S3.1 Per-article counts'!$C$2:$C$48,'S3.1 Per-article counts'!$A$2:$A$48,$B12)&"/"&SUMIFS('S3.1 Per-article counts'!$D$2:$D$48,'S3.1 Per-article counts'!$A$2:$A$48,$B12)&" ("&TEXT(SUMIFS('S3.1 Per-article counts'!$C$2:$C$48,'S3.1 Per-article counts'!$A$2:$A$48,$B12)/SUMIFS('S3.1 Per-article counts'!$D$2:$D$48,'S3.1 Per-article counts'!$A$2:$A$48,$B12),"0.0%")&")"&IF(COUNTIFS('S3.1 Per-article counts'!$A$2:$A$48,$B12,'S3.1 Per-article counts'!$D$2:$D$48,">0")<5," [k="&COUNTIFS('S3.1 Per-article counts'!$A$2:$A$48,$B12,'S3.1 Per-article counts'!$D$2:$D$48,">0")&"/5]",""))) -> 43/44 (97.7%) | E12: =IF(COUNTIFS('S3.1 Per-article counts'!$A$2:$A$48,$B12,'S3.1 Per-article counts'!$E$2:$E$48,"NS")>0,"Not supported",IF(SUMIFS('S3.1 Per-article counts'!$F$2:$F$48,'S3.1 Per-article counts'!$A$2:$A$48,$B12)=0,"Not scored",SUMIFS('S3.1 Per-article counts'!$E$2:$E$48,'S3.1 Per-article counts'!$A$2:$A$48,$B12)&"/"&SUMIFS('S3.1 Per-article counts'!$F$2:$F$48,'S3.1 Per-article counts'!$A$2:$A$48,$B12)&" ("&TEXT(SUMIFS('S3.1 Per-article counts'!$E$2:$E$48,'S3.1 Per-article counts'!$A$2:$A$48,$B12)/SUMIFS('S3.1 Per-article counts'!$F$2:$F$48,'S3.1 Per-article counts'!$A$2:$A$48,$B12),"0.0%")&")"&IF(COUNTIFS('S3.1 Per-article counts'!$A$2:$A$48,$B12,'S3.1 Per-article counts'!$F$2:$F$48,">0")<5," [k="&COUNTIFS('S3.1 Per-article counts'!$A$2:$A$48,$B12,'S3.1 Per-article counts'!$F$2:$F$48,">0")&"/5]",""))) -> 33/44 (75.0%) | F12: =IF(COUNTIFS('S3.1 Per-article counts'!$A$2:$A$48,$B12,'S3.1 Per-article counts'!$G$2:$G$48,"NS")>0,"Not supported",IF(SUMIFS('S3.1 Per-article counts'!$H$2:$H$48,'S3.1 Per-article counts'!$A$2:$A$48,$B12)=0,"Not scored",SUMIFS('S3.1 Per-article counts'!$G$2:$G$48,'S3.1 Per-article counts'!$A$2:$A$48,$B12)&"/"&SUMIFS('S3.1 Per-article counts'!$H$2:$H$48,'S3.1 Per-article counts'!$A$2:$A$48,$B12)&" ("&TEXT(SUMIFS('S3.1 Per-article counts'!$G$2:$G$48,'S3.1 Per-article counts'!$A$2:$A$48,$B12)/SUMIFS('S3.1 Per-article counts'!$H$2:$H$48,'S3.1 Per-article counts'!$A$2:$A$48,$B12),"0.0%")&")"&IF(COUNTIFS('S3.1 Per-article counts'!$A$2:$A$48,$B12,'S3.1 Per-article counts'!$H$2:$H$48,">0")<5," [k="&COUNTIFS('S3.1 Per-article counts'!$A$2:$A$48,$B12,'S3.1 Per-article counts'!$H$2:$H$48,">0")&"/5]",""))) -> 40/44 (90.9%) | G12: =IF(COUNTIFS('S3.1 Per-article counts'!$A$2:$A$48,$B12,'S3.1 Per-article counts'!$I$2:$I$48,"NS")>0,"Not supported",IF(SUMIFS('S3.1 Per-article counts'!$J$2:$J$48,'S3.1 Per-article counts'!$A$2:$A$48,$B12)=0,"Not scored",SUMIFS('S3.1 Per-article counts'!$I$2:$I$48,'S3.1 Per-article counts'!$A$2:$A$48,$B12)&"/"&SUMIFS('S3.1 Per-article counts'!$J$2:$J$48,'S3.1 Per-article counts'!$A$2:$A$48,$B12)&" ("&TEXT(SUMIFS('S3.1 Per-article counts'!$I$2:$I$48,'S3.1 Per-article counts'!$A$2:$A$48,$B12)/SUMIFS('S3.1 Per-article counts'!$J$2:$J$48,'S3.1 Per-article counts'!$A$2:$A$48,$B12),"0.0%")&")"&IF(COUNTIFS('S3.1 Per-article counts'!$A$2:$A$48,$B12,'S3.1 Per-article counts'!$J$2:$J$48,">0")<5," [k="&COUNTIFS('S3.1 Per-article counts'!$A$2:$A$48,$B12,'S3.1 Per-article counts'!$J$2:$J$48,">0")&"/5]",""))) -> 29/37 (78.4%) [k=4/5] | H12: =IF(COUNTIFS('S3.1 Per-article counts'!$A$2:$A$48,$B12,'S3.1 Per-article counts'!$K$2:$K$48,"NS")>0,"Not supported",IF(SUMIFS('S3.1 Per-article counts'!$L$2:$L$48,'S3.1 Per-article counts'!$A$2:$A$48,$B12)=0,"Not scored",SUMIFS('S3.1 Per-article counts'!$K$2:$K$48,'S3.1 Per-article counts'!$A$2:$A$48,$B12)&"/"&SUMIFS('S3.1 Per-article counts'!$L$2:$L$48,'S3.1 Per-article counts'!$A$2:$A$48,$B12)&" ("&TEXT(SUMIFS('S3.1 Per-article counts'!$K$2:$K$48,'S3.1 Per-article counts'!$A$2:$A$48,$B12)/SUMIFS('S3.1 Per-article counts'!$L$2:$L$48,'S3.1 Per-article counts'!$A$2:$A$48,$B12),"0.0%")&")"&IF(COUNTIFS('S3.1 Per-article counts'!$A$2:$A$48,$B12,'S3.1 Per-article counts'!$L$2:$L$48,">0")<5," [k="&COUNTIFS('S3.1 Per-article counts'!$A$2:$A$48,$B12,'S3.1 Per-article counts'!$L$2:$L$48,">0")&"/5]",""))) -> 2/12 (16.7%)
A13: C. Figures and captions | B13: Caption-object linkage | C13: Captions identifiable with their correct object / all numbered objects (Tabula: tables only) | D13: =IF(COUNTIFS('S3.1 Per-article counts'!$A$2:$A$48,$B13,'S3.1 Per-article counts'!$C$2:$C$48,"NS")>0,"Not supported",IF(SUMIFS('S3.1 Per-article counts'!$D$2:$D$48,'S3.1 Per-article counts'!$A$2:$A$48,$B13)=0,"Not scored",SUMIFS('S3.1 Per-article counts'!$C$2:$C$48,'S3.1 Per-article counts'!$A$2:$A$48,$B13)&"/"&SUMIFS('S3.1 Per-article counts'!$D$2:$D$48,'S3.1 Per-article counts'!$A$2:$A$48,$B13)&" ("&TEXT(SUMIFS('S3.1 Per-article counts'!$C$2:$C$48,'S3.1 Per-article counts'!$A$2:$A$48,$B13)/SUMIFS('S3.1 Per-article counts'!$D$2:$D$48,'S3.1 Per-article counts'!$A$2:$A$48,$B13),"0.0%")&")"&IF(COUNTIFS('S3.1 Per-article counts'!$A$2:$A$48,$B13,'S3.1 Per-article counts'!$D$2:$D$48,">0")<5," [k="&COUNTIFS('S3.1 Per-article counts'!$A$2:$A$48,$B13,'S3.1 Per-article counts'!$D$2:$D$48,">0")&"/5]",""))) -> 43/44 (97.7%) | E13: =IF(COUNTIFS('S3.1 Per-article counts'!$A$2:$A$48,$B13,'S3.1 Per-article counts'!$E$2:$E$48,"NS")>0,"Not supported",IF(SUMIFS('S3.1 Per-article counts'!$F$2:$F$48,'S3.1 Per-article counts'!$A$2:$A$48,$B13)=0,"Not scored",SUMIFS('S3.1 Per-article counts'!$E$2:$E$48,'S3.1 Per-article counts'!$A$2:$A$48,$B13)&"/"&SUMIFS('S3.1 Per-article counts'!$F$2:$F$48,'S3.1 Per-article counts'!$A$2:$A$48,$B13)&" ("&TEXT(SUMIFS('S3.1 Per-article counts'!$E$2:$E$48,'S3.1 Per-article counts'!$A$2:$A$48,$B13)/SUMIFS('S3.1 Per-article counts'!$F$2:$F$48,'S3.1 Per-article counts'!$A$2:$A$48,$B13),"0.0%")&")"&IF(COUNTIFS('S3.1 Per-article counts'!$A$2:$A$48,$B13,'S3.1 Per-article counts'!$F$2:$F$48,">0")<5," [k="&COUNTIFS('S3.1 Per-article counts'!$A$2:$A$48,$B13,'S3.1 Per-article counts'!$F$2:$F$48,">0")&"/5]",""))) -> 9/44 (20.5%) | F13: =IF(COUNTIFS('S3.1 Per-article counts'!$A$2:$A$48,$B13,'S3.1 Per-article counts'!$G$2:$G$48,"NS")>0,"Not supported",IF(SUMIFS('S3.1 Per-article counts'!$H$2:$H$48,'S3.1 Per-article counts'!$A$2:$A$48,$B13)=0,"Not scored",SUMIFS('S3.1 Per-article counts'!$G$2:$G$48,'S3.1 Per-article counts'!$A$2:$A$48,$B13)&"/"&SUMIFS('S3.1 Per-article counts'!$H$2:$H$48,'S3.1 Per-article counts'!$A$2:$A$48,$B13)&" ("&TEXT(SUMIFS('S3.1 Per-article counts'!$G$2:$G$48,'S3.1 Per-article counts'!$A$2:$A$48,$B13)/SUMIFS('S3.1 Per-article counts'!$H$2:$H$48,'S3.1 Per-article counts'!$A$2:$A$48,$B13),"0.0%")&")"&IF(COUNTIFS('S3.1 Per-article counts'!$A$2:$A$48,$B13,'S3.1 Per-article counts'!$H$2:$H$48,">0")<5," [k="&COUNTIFS('S3.1 Per-article counts'!$A$2:$A$48,$B13,'S3.1 Per-article counts'!$H$2:$H$48,">0")&"/5]",""))) -> Not scored | G13: =IF(COUNTIFS('S3.1 Per-article counts'!$A$2:$A$48,$B13,'S3.1 Per-article counts'!$I$2:$I$48,"NS")>0,"Not supported",IF(SUMIFS('S3.1 Per-article counts'!$J$2:$J$48,'S3.1 Per-article counts'!$A$2:$A$48,$B13)=0,"Not scored",SUMIFS('S3.1 Per-article counts'!$I$2:$I$48,'S3.1 Per-article counts'!$A$2:$A$48,$B13)&"/"&SUMIFS('S3.1 Per-article counts'!$J$2:$J$48,'S3.1 Per-article counts'!$A$2:$A$48,$B13)&" ("&TEXT(SUMIFS('S3.1 Per-article counts'!$I$2:$I$48,'S3.1 Per-article counts'!$A$2:$A$48,$B13)/SUMIFS('S3.1 Per-article counts'!$J$2:$J$48,'S3.1 Per-article counts'!$A$2:$A$48,$B13),"0.0%")&")"&IF(COUNTIFS('S3.1 Per-article counts'!$A$2:$A$48,$B13,'S3.1 Per-article counts'!$J$2:$J$48,">0")<5," [k="&COUNTIFS('S3.1 Per-article counts'!$A$2:$A$48,$B13,'S3.1 Per-article counts'!$J$2:$J$48,">0")&"/5]",""))) -> 6/37 (16.2%) [k=4/5] | H13: =IF(COUNTIFS('S3.1 Per-article counts'!$A$2:$A$48,$B13,'S3.1 Per-article counts'!$K$2:$K$48,"NS")>0,"Not supported",IF(SUMIFS('S3.1 Per-article counts'!$L$2:$L$48,'S3.1 Per-article counts'!$A$2:$A$48,$B13)=0,"Not scored",SUMIFS('S3.1 Per-article counts'!$K$2:$K$48,'S3.1 Per-article counts'!$A$2:$A$48,$B13)&"/"&SUMIFS('S3.1 Per-article counts'!$L$2:$L$48,'S3.1 Per-article counts'!$A$2:$A$48,$B13)&" ("&TEXT(SUMIFS('S3.1 Per-article counts'!$K$2:$K$48,'S3.1 Per-article counts'!$A$2:$A$48,$B13)/SUMIFS('S3.1 Per-article counts'!$L$2:$L$48,'S3.1 Per-article counts'!$A$2:$A$48,$B13),"0.0%")&")"&IF(COUNTIFS('S3.1 Per-article counts'!$A$2:$A$48,$B13,'S3.1 Per-article counts'!$L$2:$L$48,">0")<5," [k="&COUNTIFS('S3.1 Per-article counts'!$A$2:$A$48,$B13,'S3.1 Per-article counts'!$L$2:$L$48,">0")&"/5]",""))) -> 2/12 (16.7%)
A14: C. Figures and captions | B14: Figure numerical values | C14: Plotted values recovered as structured data | D14: Not supported | E14: Not supported | F14: Not supported | G14: Not supported | H14: Not supported
A15: D. Provenance and readiness | B15: Native provenance output | C15: Source location written by the tool (capability, accuracy not scored) | D15: Page + bounding box per element (JSON) | E15: None (page breaks only) | F15: Bounding box per layout region (JSON) | G15: Page-level only | H15: Page + table area (JSON)
A16: D. Provenance and readiness | B16: Hardware | C16: Minimum practical setup for local use | D16: CPU; Apple MPS / GPU optional | E16: GPU recommended | F16: CPU | G16: NVIDIA GPU required | H16: CPU (Java runtime)
A17: D. Provenance and readiness | B17: Interface and licence | C17: Documented interface; code licence | D17: Python API + CLI; MIT | E17: Python API + CLI; MIT code, CC BY-NC model weights | F17: Python API + CLI; Apache-2.0 | G17: Python pipeline; Apache-2.0 | H17: Java CLI / tabula-py; MIT
A19: Notes. Articles: P1 Bergström et al. (2013), P2 Anger (1977, scanned), P3 Graiff et al. (2017), P4 Jormalainen et al. (2016), P5 Charles et al. (2018). Values are pooled counts across articles; [k=x/y] marks measures scored on fewer articles than available. Denominators always include every item in the source article, so items missing from the output count as failures.
A20: Not supported = the tool does not produce this output by design. Not scored = not assessed in this study. olmOCR 2 was not run on P2.
A21: Numerical fidelity scores transcription only; cell placement is captured by table structure and numerical-context preservation. For P5 Table 3, olmOCR 2 placed 2/30 values in the correct matrix cells and is excluded from the pooled transcription score.
A22: Context preservation uses strict label matching (species names, chemical symbols, interaction signs, ± and ranges must be exact). P2 was excluded because its table could not be reconstructed reliably by any tool.
A23: Text fidelity was assessed on abstracts and may overstate whole-document fidelity. P2 was processed with its existing OCR text layer.
A24: Block D reports tool capabilities from documentation; provenance accuracy and runtime were not measured because runs were not made under one controlled environment.

Sheet S3.1 Per-article counts
A1: Measure | B1: Paper | C1: Docling correct (n) | D1: Docling assessed (N) | E1: Nougat correct (n) | F1: Nougat assessed (N) | G1: PP-StructureV2 correct (n) | H1: PP-StructureV2 assessed (N) | I1: olmOCR 2 correct (n) | J1: olmOCR 2 assessed (N) | K1: Tabula correct (n) | L1: Tabula assessed (N) | M1: Harmonisation note
A2: Text fidelity | B2: P1 Bergström 2013 | C2: 221 | D2: 221 | E2: 220 | F2: 221 | G2: 217 | H2: 221 | I2: 221 | J2: 221 | K2: NS | L2: NS
A3: Text fidelity | B3: P2 Anger 1977 | C3: 187 | D3: 187 | E3: 182 | F3: 187 | G3: 186 | H3: 187 | I3: not run | J3: not run | K3: NS | L3: NS | M3: olmOCR 2 not run on P2
A4: Text fidelity | B4: P3 Graiff 2017 | C4: 254 | D4: 254 | E4: 22 | F4: 254 | G4: 238 | H4: 254 | I4: 254 | J4: 254 | K4: NS | L4: NS | M4: Nougat retained only the final abstract fragment
A5: Text fidelity | B5: P4 Jormalainen 2016 | C5: 262 | D5: 262 | E5: 259 | F5: 262 | G5: 250 | H5: 262 | I5: 261 | J5: 262 | K5: NS | L5: NS
A6: Text fidelity | B6: P5 Charles 2018 | C6: 337 | D6: 341 | E6: 0 | F6: 341 | G6: 330 | H6: 341 | I6: 332 | J6: 341 | K6: NS | L6: NS | M6: Nougat output starts at the Introduction
A7: Reading continuity | B7: P1 Bergström 2013 | C7: 6 | D7: 9 | E7: 3 | F7: 9 | G7: not scored | H7: not scored | I7: not scored | J7: not scored | K7: NS | L7: NS
A8: Reading continuity | B8: P2 Anger 1977 | C8: 3 | D8: 7 | E8: 0 | F8: 7 | G8: not scored | H8: not scored | I8: not run | J8: not run | K8: NS | L8: NS | M8: Nougat: missing objects counted as failures (was 0/4)
A9: Reading continuity | B9: P3 Graiff 2017 | C9: 7 | D9: 10 | E9: 0 | F9: 10 | G9: not scored | H9: not scored | I9: 3 | J9: 10 | K9: NS | L9: NS | M9: Missing objects counted as failures (Nougat was 0/6, olmOCR 2 3/7)
A10: Reading continuity | B10: P4 Jormalainen 2016 | C10: 6 | D10: 7 | E10: 1 | F10: 7 | G10: not scored | H10: not scored | I10: 2 | J10: 7 | K10: NS | L10: NS
A11: Reading continuity | B11: P5 Charles 2018 | C11: 3 | D11: 11 | E11: 1 | F11: 11 | G11: not scored | H11: not scored | I11: not scored | J11: not scored | K11: NS | L11: NS | M11: Nougat: missing objects counted as failures (was 1/9)
A12: Table coverage | B12: P1 Bergström 2013 | C12: 4 | D12: 4 | E12: 4 | F12: 4 | G12: 4 | H12: 4 | I12: 2 | J12: 4 | K12: 4 | L12: 4 | M12: olmOCR 2: Tables 3-4 caption + empty markup only, counted as not retained
A13: Table coverage | B13: P2 Anger 1977 | C13: 2 | D13: 2 | E13: 1 | F13: 2 | G13: 2 | H13: 2 | I13: not run | J13: not run | K13: 1 | L13: 2
A14: Table coverage | B14: P3 Graiff 2017 | C14: 1 | D14: 1 | E14: 1 | F14: 1 | G14: 1 | H14: 1 | I14: 1 | J14: 1 | K14: 1 | L14: 1
A15: Table coverage | B15: P4 Jormalainen 2016 | C15: 2 | D15: 2 | E15: 2 | F15: 2 | G15: 2 | H15: 2 | I15: 2 | J15: 2 | K15: 1 | L15: 2
A16: Table coverage | B16: P5 Charles 2018 | C16: 3 | D16: 3 | E16: 3 | F16: 3 | G16: 3 | H16: 3 | I16: 3 | J16: 3 | K16: 3 | L16: 3 | M16: Nougat Table 2 present only as fragment (fails structure)
A17: Basic table structure | B17: P1 Bergström 2013 | C17: 4 | D17: 4 | E17: 3 | F17: 4 | G17: 3 | H17: 4 | I17: 2 | J17: 4 | K17: 3 | L17: 4
A18: Basic table structure | B18: P2 Anger 1977 | C18: 1 | D18: 2 | E18: 0 | F18: 2 | G18: 1 | H18: 2 | I18: not run | J18: not run | K18: 0 | L18: 2
A19: Basic table structure | B19: P3 Graiff 2017 | C19: 1 | D19: 1 | E19: 1 | F19: 1 | G19: 1 | H19: 1 | I19: 1 | J19: 1 | K19: 0 | L19: 1
A20: Basic table structure | B20: P4 Jormalainen 2016 | C20: 2 | D20: 2 | E20: 2 | F20: 2 | G20: 2 | H20: 2 | I20: 2 | J20: 2 | K20: 0 | L20: 2
A21: Basic table structure | B21: P5 Charles 2018 | C21: 2 | D21: 3 | E21: 1 | F21: 3 | G21: 2 | H21: 3 | I21: 2 | J21: 3 | K21: 1 | L21: 3 | M21: olmOCR 2 Table 3 (filled diagonal) now fails, as for Nougat (was 3/3); Tabula derived from note: only Table 3 grid usable
A22: Table header hierarchy | B22: P1 Bergström 2013 | C22: 3 | D22: 4 | E22: 2 | F22: 4 | G22: 2 | H22: 4 | I22: 2 | J22: 4 | K22: 0 | L22: 4
A23: Table header hierarchy | B23: P2 Anger 1977 | C23: 0 | D23: 1 | E23: 0 | F23: 1 | G23: 0 | H23: 1 | I23: not run | J23: not run | K23: 0 | L23: 1 | M23: Table 1 only (Table 2 flat; Docling was 1/2)
A24: Table header hierarchy | B24: P4 Jormalainen 2016 | C24: 1 | D24: 1 | E24: 0 | F24: 1 | G24: 1 | H24: 1 | I24: 1 | J24: 1 | K24: 0 | L24: 1 | M24: Table 2 only. P3 and P5 have no nested headers
A25: Table numerical fidelity | B25: P1 Bergström 2013 | C25: 110 | D25: 110 | E25: 110 | F25: 110 | G25: 110 | H25: 110 | I25: 0 | J25: 110 | K25: 110 | L25: 110 | M25: Table 3
A26: Table numerical fidelity | B26: P2 Anger 1977 | C26: 20 | D26: 30 | E26: 0 | F26: 30 | G26: 30 | H26: 30 | I26: not run | J26: not run | K26: 21 | L26: 30 | M26: Same sample for all tools: Table 1, Hydrobia ulvae, 30 entries (Docling/Nougat were 60-entry samples)
A27: Table numerical fidelity | B27: P3 Graiff 2017 | C27: 84 | D27: 84 | E27: 82 | F27: 84 | G27: 84 | H27: 84 | I27: 83 | J27: 84 | K27: 84 | L27: 84 | M27: Table 1, all entries
A28: Table numerical fidelity | B28: P4 Jormalainen 2016 | C28: 53 | D28: 58 | E28: 58 | F28: 58 | G28: 58 | H28: 58 | I28: 58 | J28: 58 | K28: 35 | L28: 58 | M28: Both tables; Tabula missed Table 1 (23 entries counted as missed)
A29: Table numerical fidelity | B29: P5 Charles 2018 | C29: 30 | D29: 30 | E29: 29 | F29: 30 | G29: 30 | H29: 30 | I29: not scored | J29: not scored | K29: 30 | L29: 30 | M29: Table 3, transcription only (cell placement scored under structure). olmOCR 2 scored only under strict cell matching (2/30), so excluded here
A30: Numerical-context preservation | B30: P1 Bergström 2013 | C30: 21 | D30: 21 | E30: 21 | F30: 21 | G30: 7 | H30: 21 | I30: 21 | J30: 21 | K30: 0 | L30: 21 | M30: Table 1. Tabula: values only readable after manual splitting, counted 0
A31: Numerical-context preservation | B31: P3 Graiff 2017 | C31: 84 | D31: 84 | E31: 82 | F31: 84 | G31: 30 | H31: 84 | I31: 84 | J31: 84 | K31: not scored | L31: not scored | M31: Table 1
A32: Numerical-context preservation | B32: P4 Jormalainen 2016 | C32: 35 | D32: 35 | E32: 25 | F32: 35 | G32: 35 | H32: 35 | I32: 30 | J32: 35 | K32: not scored | L32: not scored | M32: Table 2
A33: Numerical-context preservation | B33: P5 Charles 2018 | C33: 24 | D33: 24 | E33: 14 | F33: 24 | G33: not scored | H33: not scored | I33: 4 | J33: 24 | K33: not scored | L33: not scored | M33: Table 1, salinity mean ± SEM
A34: Figure visual preservation | B34: P1 Bergström 2013 | C34: 4 | D34: 5 | E34: NS | F34: NS | G34: 5 | H34: 5 | I34: NS | J34: NS | K34: NS | L34: NS
A35: Figure visual preservation | B35: P2 Anger 1977 | C35: 5 | D35: 5 | E35: NS | F35: NS | G35: not scored | H35: not scored | I35: not run | J35: not run | K35: NS | L35: NS | M35: PP-StructureV2 crops not checked for P2-P5
A36: Figure visual preservation | B36: P3 Graiff 2017 | C36: 9 | D36: 9 | E36: NS | F36: NS | G36: not scored | H36: not scored | I36: NS | J36: NS | K36: NS | L36: NS
A37: Figure visual preservation | B37: P4 Jormalainen 2016 | C37: 5 | D37: 5 | E37: NS | F37: NS | G37: not scored | H37: not scored | I37: NS | J37: NS | K37: NS | L37: NS
A38: Figure visual preservation | B38: P5 Charles 2018 | C38: 8 | D38: 8 | E38: NS | F38: NS | G38: not scored | H38: not scored | I38: NS | J38: NS | K38: NS | L38: NS
A39: Caption coverage | B39: P1 Bergström 2013 | C39: 8 | D39: 9 | E39: 8 | F39: 9 | G39: 9 | H39: 9 | I39: 8 | J39: 9 | K39: 1 | L39: 4 | M39: Docling corrected from '8/9 (100%)'
A40: Caption coverage | B40: P2 Anger 1977 | C40: 7 | D40: 7 | E40: 4 | F40: 7 | G40: 7 | H40: 7 | I40: not run | J40: not run | K40: 0 | L40: 2
...

Sheet S3.2 Test articles
A1: ID | B1: Article | C1: Journal | D1: PDF type | E1: Tables | F1: Figures | G1: Why included
A2: P1 | B2: Bergström et al. 2013 | C2: Marine Ecology Progress Series 485 | D2: Born-digital | E2: 4 | F2: 5 | G2: ± and ranges by area/phase; symbol-coded species table; grouped-header statistics tables
A3: P2 | B3: Anger 1977 | C3: Int. Revue ges. Hydrobiol. 62 | D3: Scanned (existing OCR layer) | E3: 2 | F3: 5 | G3: Scanned route; large rotated table across two pages with three-level header
A4: P3 | B4: Graiff et al. 2017 | C4: Botanica Marina (author preprint) | D4: Born-digital | E4: 1 | F4: 9 | G4: Experimental stressor study; row-grouped ANOVA table; statistics in text; page noise
A5: P4 | B5: Jormalainen et al. 2016 | C5: Biological Invasions 18 | D5: Born-digital | E5: 2 | F5: 5 | G5: Clean baseline layout; grouped column headers
A6: P5 | B6: Charles et al. 2018 | C6: Estuarine, Coastal and Shelf Science 212 | D6: Born-digital | E6: 3 | F6: 8 | G6: Non-Baltic; species × site table; triangular similarity matrix; ± SEM

Sheet S3.3 Tool versions
A1: Table S3.3. Tool versions, run mode and settings used in the empirical evaluation.
A3: Tool | B3: Version used | C3: Run mode | D3: Key settings | E3: Hardware (CPU/GPU, RAM) | F3: Operating system | G3: Run date(s) | H3: Articles processed | I3: Licence | J3: Code repository | K3: Notes
A4: Docling | H4: P1–P5 | I4: MIT | J4: https://github.com/docling-project/docling
A5: Nougat | H5: P1–P5 | I5: MIT (code); CC BY-NC 4.0 (model weights) | J5: https://github.com/facebookresearch/nougat
A6: PP-StructureV2 (PaddleOCR) | H6: P1–P5 | I6: Apache-2.0 | J6: https://github.com/PaddlePaddle/PaddleOCR
A7: olmOCR 2 | H7: P1, P3, P4, P5 | I7: Apache-2.0 | J7: https://github.com/allenai/olmocr | K7: Not run on P2 (Anger 1977)
A8: Tabula | H8: P1–P5 | I8: MIT | J8: https://github.com/tabulapdf/tabula-java | K8: State whether tabula-java, tabula-py or the desktop app was used
A10: How to fill: complete the yellow cells. Run mode has a drop-down list.
A11: Version used: the exact version string, e.g. from 'pip show docling' or the release tag; for web demos give the demo URL and access date.
A12: Key settings: anything changed from defaults (OCR on/off, table mode, page range, model size, prompt or temperature for olmOCR 2).
A13: Licence and repository: from each tool's public repository; check against the version you ran.

Sheet S3.4 Assessment notes
A1: Table S3.4. Original per-article assessment notes, as recorded before harmonisation. Harmonised counts used in Table 6 are in S3.1; differences are explained in its notes column.
A3: Article | B3: Evaluation dimension | C3: Tool | D3: Original result | E3: Scope / evidence note | F3: Remark
A4: P1 Bergström 2013 | B4: Text fidelity | C4: Docling | D4: 221/221 (100%) | E4: Abstract only; case normalized, punctuation excluded, source line-break hyphenation removed
A5: P1 Bergström 2013 | B5: Text fidelity | C5: Nougat | D5: 220/221 (99.5%) | E5: Abstract only; one substitution: “eelpout” → “eelout”
A6: P1 Bergström 2013 | B6: Text fidelity | C6: PP-StructureV2 | D6: 217/221 (98.2%) | E6: Abstract only; case normalized, punctuation excluded, line-break hyphenation removed; four word substitutions
A7: P1 Bergström 2013 | B7: Text fidelity | C7: olmOCR 2 | D7: 221/221 (100%) | E7: Abstract only; verified token-for-token after case normalization, punctuation exclusion, and removal of source line-break hyphenation
A8: P1 Bergström 2013 | B8: Text fidelity | C8: Tabula | D8: Not applicable | E8: Table extractor; the abstract is not included in this output
A9: P1 Bergström 2013 | B9: Reading continuity | C9: Docling | D9: 6/9 (66.7%) | E9: All 4 table and 5 figure insertions
A10: P1 Bergström 2013 | B10: Reading continuity | C10: Nougat | D10: 3/9 (33.3%) | E10: Figures 1–4 and Tables 2–3 interrupt sentences; figure insertions consist of captions
A11: P1 Bergström 2013 | B11: Reading continuity | C11: PP-StructureV2 | D11: Not evaluated | E11: Reordering and duplicated/interleaved content observed; the nine insertion locations were not individually scored
A12: P1 Bergström 2013 | B12: Reading continuity | C12: olmOCR 2 | D12: Not evaluated | E12: Figure 1 interrupts “spe–cies”; Table 2 and Figure 2 separate “The Shannon index differed” from “among areas.” Missing page 7 and 9 body text prevents a complete nine-insertion score
A13: P1 Bergström 2013 | B13: Reading continuity | C13: Tabula | D13: Not applicable | E13: Output consists of table candidates rather than a reconstructed document
A14: P1 Bergström 2013 | B14: Table coverage | C14: Docling | D14: 4/4 (100%) | E14: Entire article
A15: P1 Bergström 2013 | B15: Table coverage | C15: Nougat | D15: 4/4 (100%) | E15: Includes incomplete Table 4
... A251: P5 Charles 2018 | B251: Text fidelity | C251: olmOCR 2 | D251: 332/341 (97.4%) | E251: Abstract only; Unicode and case normalized, punctuation excluded, source line-break hyphenation removed. Errors include “cryptogenic” → “cryptogam” and replacement of the crab’s scientific name.
A252: P5 Charles 2018 | B252: Text fidelity | C252: Tabula | D252: Tables 1, 2 and 3 appear in the export. | E252: Detection does not establish accuracy. | F252: Tabula notes for this article are offset from the dimension labels in the source sheet; read them as a set, not row by row.
A253: P5 Charles 2018 | B253: Reading continuity | C253: Docling | D253: 3/11 (27.3%) | E253: All three tables and eight figures. Table 1 and Figures 3 and 8 pass. A consecutive run containing Figure 4, Table 2, Figure 5, Table 3 and Figure 6 splits “…has been reported … in French ports…”. Each numbered object within that interrupted sentence is counted as a failure. Figures 1, 2 and 7 also interrupt sentences.
